<?xml version="1.0" encoding="utf-8" ?>
<robot name="jaka_zu7_robot"> 

    <link name="jaka_zu7_base_link">
      <inertial>
        <origin xyz="0.00096371 8.8222E-08 0.019555" rpy="0 0 0" />
        <mass value="4.0392" />
        <inertia ixx="0.0048763" ixy="-1.8056E-07" ixz="2.5196E-05" iyy="0.0068003"
          iyz="-1.7678E-09" izz="0.010618" />
      </inertial>

      <visual>
        <origin xyz="0 0 0" rpy="0 0 0" />
        <geometry>
          <mesh filename="../meshes/zu7/collision/base_link.STL" />
        </geometry>
        <material name="">
          <color rgba="0.84706 0.84706 0.84706 1" />
        </material>
      </visual>
      <collision>
        <origin xyz="0 0 0" rpy="0 0 0" />
        <geometry>
          <mesh filename="../meshes/zu7/collision/link_0.STL" />
        </geometry>
      </collision>
    </link>

    <link name="jaka_zu7_link_1">
      <inertial>
        <origin xyz="-2.5186E-07 0.0033226 -0.001509" rpy="0 0 0" />
        <mass value="15.135" />
        <inertia ixx="0.044302" ixy="1.5349E-07" ixz="-6.1966E-07" iyy="0.043091"
          iyz="1.4326E-05" izz="0.030523" />
      </inertial>

      <visual>
        <origin xyz="0 0 0" rpy="0 0 0" />
        <geometry>
          <mesh filename="../meshes/zu7/collision/link_1.STL" />
        </geometry>
        <material name="">
          <color rgba="0.84706 0.84706 0.84706 1" />
        </material>
      </visual>
      <collision>
        <origin xyz="0 0 0" rpy="0 0 0" />
        <geometry>
          <mesh filename="../meshes/zu7/collision/link_1.STL" />
        </geometry>
      </collision>
    </link>

    <link name="jaka_zu7_link_2">
      <inertial>
        <origin xyz="0.18 8.8001E-09 -0.14308" rpy="0 0 0" />
        <mass value="42.872" />
        <inertia ixx="0.1014" ixy="-1.1106E-06" ixz="-1.3363E-07" iyy="1.1119"
          iyz="2.9045E-08" izz="1.0844" />
      </inertial>

      <visual>
        <origin xyz="0 0 0" rpy="0 0 0" />
        <geometry>
          <mesh filename="../meshes/zu7/collision/link_2.STL" />
        </geometry>
        <material name="">
          <color rgba="0.84706 0.84706 0.84706 1" />
        </material>
      </visual>
      <collision>
        <origin xyz="0 0 0" rpy="0 0 0" />
        <geometry>
          <mesh filename="../meshes/zu7/collision/link_2.STL" />
        </geometry>
      </collision>
    </link>

    <link name="jaka_zu7_link_3">
      <inertial>
        <origin xyz="0.15515 5.4643E-08 -0.012576" rpy="0 0 0" />
        <mass value="16.562" />
        <inertia ixx="0.020968" ixy="-3.9001E-06" ixz="-0.018394" iyy="0.28365"
          iyz="-1.2859E-07" izz="0.27848" />
      </inertial>

      <visual>
        <origin xyz="0 0 0" rpy="0 0 0" />
        <geometry>
          <mesh filename="../meshes/zu7/collision/link_3.STL" />
        </geometry>
        <material name="">
          <color rgba="0.84706 0.84706 0.84706 1" />
        </material>
      </visual>
      <collision>
        <origin xyz="0 0 0" rpy="0 0 0" />
        <geometry>
          <mesh filename="../meshes/zu7/collision/link_3.STL" />
        </geometry>
      </collision>
    </link>

    <link name="jaka_zu7_link_4">
      <inertial>
        <origin xyz="-2.1345E-06 -0.0058004 0.0026717" rpy="0 0 0" />
        <mass value="5.5525" />
        <inertia ixx="0.0092564" ixy="1.1341E-07" ixz="-1.2578E-08" iyy="0.0052251"
          iyz="-8.3499E-05" izz="0.0089683" />
      </inertial>

      <visual>
        <origin xyz="0 0 0" rpy="0 0 0" />
        <geometry>
          <mesh filename="../meshes/zu7/collision/link_4.STL" />
        </geometry>
        <material name="">
          <color rgba="0.84706 0.84706 0.84706 1" />
        </material>
      </visual>
      <collision>
        <origin xyz="0 0 0" rpy="0 0 0" />
        <geometry>
          <mesh filename="../meshes/zu7/collision/link_4.STL" />
        </geometry>
      </collision>
    </link>

    <link name="jaka_zu7_link_5">
      <inertial>
        <origin xyz="-2.0304E-06 -0.0028889 -0.0023424" rpy="0 0 0" />
        <mass value="6.3339" />
        <inertia ixx="0.012993" ixy="-1.0764E-07" ixz="5.8559E-09" iyy="0.0058454"
          iyz="4.5426E-05" izz="0.0127" />
      </inertial>

      <visual>
        <origin xyz="0 0 0" rpy="0 0 0" />
        <geometry>
          <mesh filename="../meshes/zu7/collision/link_5.STL" />
        </geometry>
        <material name="">
          <color rgba="0.84706 0.84706 0.84706 1" />
        </material>
      </visual>
      <collision>
        <origin xyz="0 0 0" rpy="0 0 0" />
        <geometry>
          <mesh filename="../meshes/zu7/collision/link_5.STL" />
        </geometry>
      </collision>
    </link>

    <link name="jaka_zu7_link_6">
      <inertial>
        <origin xyz="2.7652E-05 -1.3485E-05 -0.021245" rpy="0 0 0" />
        <mass value="1.4169" />
        <inertia ixx="0.00071853" ixy="-6.9778E-07" ixz="-6.378E-07" iyy="0.00072375"
          iyz="8.3072E-07" izz="0.0011337" />
      </inertial>

      <visual>
        <origin xyz="0 0 0" rpy="0 0 0" />
        <geometry>
          <mesh filename="../meshes/zu7/collision/link_6.STL" />
        </geometry>
        <material name="">
          <color rgba="0.84706 0.84706 0.84706 1" />
        </material>
      </visual>
      <collision>
        <origin xyz="0 0 0" rpy="0 0 0" />
        <geometry>
          <mesh filename="../meshes/zu7/collision/link_6.STL" />
        </geometry>
      </collision>
    </link>

    <link name="jaka_zu7_tool0" />

    <!-- <joint name="jaka_zu7_base_joint" type="fixed">
      <xacro:insert_block name="origin" />
      <parent link="${parent}" />
      <child link="jaka_zu7_base_link" />
    </joint> -->

    <joint name="jaka_zu7_joint_1" type="revolute">
      <origin xyz="0 0 0.12015" rpy="0 0 0" />
      <parent link="jaka_zu7_base_link" />
      <child link="jaka_zu7_link_1" />
      <axis xyz="0 0 1" />
      <limit lower="-6.28" upper="6.28" effort="2000" velocity="1.57" />
    </joint>

    <joint name="jaka_zu7_joint_2" type="revolute">
      <origin xyz="0 0 0" rpy="1.5708 0 0" />
      <parent link="jaka_zu7_link_1" />
      <child link="jaka_zu7_link_2" />
      <axis xyz="0 0 1" />
      <limit lower="-1.48" upper="4.62" effort="1500" velocity="1.57" />
    </joint>

    <joint name="jaka_zu7_joint_3" type="revolute">
      <origin xyz="0.36 0 0" rpy="0 0 0" />
      <parent link="jaka_zu7_link_2" />
      <child link="jaka_zu7_link_3" />
      <axis xyz="0 0 1" />
      <limit lower="-3.05" upper="3.05" effort="1500" velocity="1.57" />
    </joint>

    <joint name="jaka_zu7_joint_4" type="revolute">
      <origin xyz="0.30353 0 -0.11501" rpy="0 0 0" />
      <parent link="jaka_zu7_link_3" />
      <child link="jaka_zu7_link_4" />
      <axis xyz="0 0 1" />
      <limit lower="-1.48" upper="4.62" effort="1000" velocity="1.57" />
    </joint>

    <joint name="jaka_zu7_joint_5" type="revolute">
      <origin xyz="0 -0.1135 0" rpy="1.5708 0 0" />
      <parent link="jaka_zu7_link_4" />
      <child link="jaka_zu7_link_5" />
      <axis xyz="0 0 1" />
      <limit lower="-6.28" upper="6.28" effort="1000" velocity="1.57" />
    </joint>

    <joint name="jaka_zu7_joint_6" type="revolute">
      <origin xyz="0 0.107 0" rpy="-1.5708 0 0" />
      <parent link="jaka_zu7_link_5" />
      <child link="jaka_zu7_link_6" />
      <axis xyz="0 0 1" />
      <limit lower="-6.28" upper="6.28" effort="1000" velocity="1.57" />
    </joint>

    <joint name="jaka_zu7_joint_6-tool0" type="fixed">
      <parent link="jaka_zu7_link_6" />
      <child link="jaka_zu7_tool0" />
      <origin xyz="0 0 0" rpy="0 0 0" />
    </joint>

</robot>