<?xml version="1.0" ?>
<!-- =================================================================================== -->
<!-- |    This document was autogenerated by xacro from urdf/ur10_robot.urdf.xacro     | -->
<!-- |    EDITING THIS FILE BY HAND IS NOT RECOMMENDED                                 | -->
<!-- =================================================================================== -->
<robot name="ur10" xmlns:xacro="http://www.ros.org/wiki/xacro">
  <!-- common stuff -->
  <gazebo>
    <plugin filename="libgazebo_ros_control.so" name="ros_control">
      <!--robotNamespace>/</robotNamespace-->
      <!--robotSimType>gazebo_ros_control/DefaultRobotHWSim</robotSimType-->
    </plugin>
    <!--
    <plugin name="gazebo_ros_power_monitor_controller" filename="libgazebo_ros_power_monitor.so">
      <alwaysOn>true</alwaysOn>
      <updateRate>1.0</updateRate>
      <timeout>5</timeout>
      <powerStateTopic>power_state</powerStateTopic>
      <powerStateRate>10.0</powerStateRate>
      <fullChargeCapacity>87.78</fullChargeCapacity>     
      <dischargeRate>-474</dischargeRate>
      <chargeRate>525</chargeRate>
      <dischargeVoltage>15.52</dischargeVoltage>
      <chargeVoltage>16.41</chargeVoltage>
    </plugin>
-->
  </gazebo>
  <!-- ur10 -->
  <!-- arm -->
  <link name="base_link">
    <visual>
      <geometry>
        <mesh filename="./meshes/visual/Base.dae"/>
      </geometry>
    </visual>
    <collision>
      <geometry>
        <mesh filename="./meshes/collision/Base.dae"/>
      </geometry>
    </collision>
    <inertial>
      <mass value="4.0"/>
      <origin rpy="0 0 0" xyz="0.0 0.0 0.0"/>
      <inertia ixx="0.0061063308908" ixy="0.0" ixz="0.0" iyy="0.0061063308908" iyz="0.0" izz="0.01125"/>
    </inertial>
  </link>
  <joint name="shoulder_pan_joint" type="revolute">
    <parent link="base_link"/>
    <child link="shoulder_link"/>
    <origin rpy="0.0 0.0 0.0" xyz="0.0 0.0 0.1273"/>
    <axis xyz="0 0 1"/>
    <limit effort="330.0" lower="-6.2831853" upper="6.2831853" velocity="2.16"/>
    <dynamics damping="0.0" friction="0.0"/>
  </joint>
  <link name="shoulder_link">
    <visual>
      <geometry>
        <mesh filename="./meshes/visual/Shoulder.dae"/>
      </geometry>
    </visual>
    <collision>
      <geometry>
        <mesh filename="./meshes/collision/Shoulder.dae"/>
      </geometry>
    </collision>
    <inertial>
      <mass value="7.778"/>
      <origin rpy="0 0 0" xyz="0.0 0.0 0.0"/>
      <inertia ixx="0.0314743125769" ixy="0.0" ixz="0.0" iyy="0.0314743125769" iyz="0.0" izz="0.021875625"/>
    </inertial>
  </link>
  <joint name="shoulder_lift_joint" type="revolute">
    <parent link="shoulder_link"/>
    <child link="upper_arm_link"/>
    <origin rpy="0.0 1.570796325 0.0" xyz="0.0 0.220941 0.0"/>
    <axis xyz="0 1 0"/>
    <limit effort="330.0" lower="-6.2831853" upper="6.2831853" velocity="2.16"/>
    <dynamics damping="0.0" friction="0.0"/>
  </joint>
  <link name="upper_arm_link">
    <visual>
      <geometry>
        <mesh filename="./meshes/visual/UpperArm.dae"/>
      </geometry>
    </visual>
    <collision>
      <geometry>
        <mesh filename="./meshes/collision/UpperArm.dae"/>
      </geometry>
    </collision>
    <inertial>
      <mass value="12.93"/>
      <origin rpy="0 0 0" xyz="0.0 0.0 0.306"/>
      <inertia ixx="0.421753803798" ixy="0.0" ixz="0.0" iyy="0.421753803798" iyz="0.0" izz="0.036365625"/>
    </inertial>
  </link>
  <joint name="elbow_joint" type="revolute">
    <parent link="upper_arm_link"/>
    <child link="forearm_link"/>
    <origin rpy="0.0 0.0 0.0" xyz="0.0 -0.1719 0.612"/>
    <axis xyz="0 1 0"/>
    <limit effort="150.0" lower="-6.2831853" upper="6.2831853" velocity="3.15"/>
    <dynamics damping="0.0" friction="0.0"/>
  </joint>
  <link name="forearm_link">
    <visual>
      <geometry>
        <mesh filename="./meshes/visual/Forearm.dae"/>
      </geometry>
    </visual>
    <collision>
      <geometry>
        <mesh filename="./meshes/collision/Forearm.dae"/>
      </geometry>
    </collision>
    <inertial>
      <mass value="3.87"/>
      <origin rpy="0 0 0" xyz="0.0 0.0 0.28615"/>
      <inertia ixx="0.111069694097" ixy="0.0" ixz="0.0" iyy="0.111069694097" iyz="0.0" izz="0.010884375"/>
    </inertial>
  </link>
  <joint name="wrist_1_joint" type="revolute">
    <parent link="forearm_link"/>
    <child link="wrist_1_link"/>
    <origin rpy="0.0 1.570796325 0.0" xyz="0.0 0.0 0.5723"/>
    <axis xyz="0 1 0"/>
    <limit effort="54.0" lower="-6.2831853" upper="6.2831853" velocity="3.2"/>
    <dynamics damping="0.0" friction="0.0"/>
  </joint>
  <link name="wrist_1_link">
    <visual>
      <geometry>
        <mesh filename="./meshes/visual/Wrist1.dae"/>
      </geometry>
    </visual>
    <collision>
      <geometry>
        <mesh filename="./meshes/collision/Wrist1.dae"/>
      </geometry>
    </collision>
    <inertial>
      <mass value="1.96"/>
      <origin rpy="0 0 0" xyz="0.0 0.0 0.0"/>
      <inertia ixx="0.0051082479567" ixy="0.0" ixz="0.0" iyy="0.0051082479567" iyz="0.0" izz="0.0055125"/>
    </inertial>
  </link>
  <joint name="wrist_2_joint" type="revolute">
    <parent link="wrist_1_link"/>
    <child link="wrist_2_link"/>
    <origin rpy="0.0 0.0 0.0" xyz="0.0 0.1149 0.0"/>
    <axis xyz="0 0 1"/>
    <limit effort="54.0" lower="-6.2831853" upper="6.2831853" velocity="3.2"/>
    <dynamics damping="0.0" friction="0.0"/>
  </joint>
  <link name="wrist_2_link">
    <visual>
      <geometry>
        <mesh filename="./meshes/visual/Wrist2.dae"/>
      </geometry>
    </visual>
    <collision>
      <geometry>
        <mesh filename="./meshes/collision/Wrist2.dae"/>
      </geometry>
    </collision>
    <inertial>
      <mass value="1.96"/>
      <origin rpy="0 0 0" xyz="0.0 0.0 0.0"/>
      <inertia ixx="0.0051082479567" ixy="0.0" ixz="0.0" iyy="0.0051082479567" iyz="0.0" izz="0.0055125"/>
    </inertial>
  </link>
  <joint name="wrist_3_joint" type="revolute">
    <parent link="wrist_2_link"/>
    <child link="wrist_3_link"/>
    <origin rpy="0.0 0.0 0.0" xyz="0.0 0.0 0.1157"/>
    <axis xyz="0 1 0"/>
    <limit effort="54.0" lower="-6.2831853" upper="6.2831853" velocity="3.2"/>
    <dynamics damping="0.0" friction="0.0"/>
  </joint>
  <link name="wrist_3_link">
    <visual>
      <geometry>
        <mesh filename="./meshes/visual/Wrist3.dae"/>
      </geometry>
    </visual>
    <collision>
      <geometry>
        <mesh filename="./meshes/collision/Wrist3.dae"/>
      </geometry>
    </collision>
    <inertial>
      <mass value="0.202"/>
      <origin rpy="0 0 0" xyz="0.0 0.0 0.0"/>
      <inertia ixx="0.000526462289415" ixy="0.0" ixz="0.0" iyy="0.000526462289415" iyz="0.0" izz="0.000568125"/>
    </inertial>
  </link>
  <joint name="ee_fixed_joint" type="fixed">
    <parent link="wrist_3_link"/>
    <child link="ee_link"/>
    <origin rpy="0.0 0.0 1.570796325" xyz="0.0 0.0922 0.0"/>
  </joint>
  <link name="ee_link"/>
  <transmission name="shoulder_pan_trans">
    <type>transmission_interface/SimpleTransmission</type>
    <joint name="shoulder_pan_joint"/>
    <actuator name="shoulder_pan_motor">
      <hardwareInterface>EffortJointInterface</hardwareInterface>
      <mechanicalReduction>1</mechanicalReduction>
    </actuator>
  </transmission>
  <transmission name="shoulder_lift_trans">
    <type>transmission_interface/SimpleTransmission</type>
    <joint name="shoulder_lift_joint"/>
    <actuator name="shoulder_lift_motor">
      <hardwareInterface>EffortJointInterface</hardwareInterface>
      <mechanicalReduction>1</mechanicalReduction>
    </actuator>
  </transmission>
  <transmission name="elbow_trans">
    <type>transmission_interface/SimpleTransmission</type>
    <joint name="elbow_joint"/>
    <actuator name="elbow_motor">
      <hardwareInterface>EffortJointInterface</hardwareInterface>
      <mechanicalReduction>1</mechanicalReduction>
    </actuator>
  </transmission>
  <transmission name="wrist_1_trans">
    <type>transmission_interface/SimpleTransmission</type>
    <joint name="wrist_1_joint"/>
    <actuator name="wrist_1_motor">
      <hardwareInterface>EffortJointInterface</hardwareInterface>
      <mechanicalReduction>1</mechanicalReduction>
    </actuator>
  </transmission>
  <transmission name="wrist_2_trans">
    <type>transmission_interface/SimpleTransmission</type>
    <joint name="wrist_2_joint"/>
    <actuator name="wrist_2_motor">
      <hardwareInterface>EffortJointInterface</hardwareInterface>
      <mechanicalReduction>1</mechanicalReduction>
    </actuator>
  </transmission>
  <transmission name="wrist_3_trans">
    <type>transmission_interface/SimpleTransmission</type>
    <joint name="wrist_3_joint"/>
    <actuator name="wrist_3_motor">
      <hardwareInterface>EffortJointInterface</hardwareInterface>
      <mechanicalReduction>1</mechanicalReduction>
    </actuator>
  </transmission>

  <!-- Frame coincident with all-zeros TCP on UR controller -->
  <link name="tool0"/>
  <joint name="wrist_3_link-tool0_fixed_joint" type="fixed">
    <origin rpy="-1.57079632679 0 0" xyz="0 0.0922 0"/>
    <parent link="wrist_3_link"/>
    <child link="tool0"/>
  </joint>

  <link name="robotiq_coupler">
    <visual>
      <geometry>
        <mesh filename="./meshes/robotiq2f85/robotiq_85_coupler.stl" />
      </geometry>
    </visual>
    <collision>
      <geometry>
        <mesh filename="./meshes/robotiq2f85/robotiq_85_coupler.stl" />
      </geometry>
    </collision>
    <inertial>
      <origin xyz="2.073e-05   1.45286e-03  -1.1049e-03" rpy="0 0 0" />
      <mass value="0.168" />
      <inertia ixx="6.69695624e-05" ixy="5.21511788e-09" ixz="-2.74383009e-08" 
              iyy="7.85088161e-05" iyz="5.41105193e-07" izz="1.41819717e-04"/>
    </inertial>
  </link>

  <joint name="robotiq_coupler_joint" type="fixed">
    <origin xyz="0 0 0.004" rpy="0 0 -1.57079632679" />
    <parent link="tool0"/>
    <child link="robotiq_coupler"/>
  </joint>

  <!-- <gazebo reference="robotiq_coupler">
    <mu1>0.9</mu1>
    <mu2>0.9</mu2>
    <material>Gazebo/FlatBlack</material>
  </gazebo> -->

  <!--<link name="robotiq_85_base_link">
    <visual>
      <geometry>
        <mesh filename="./meshes/robotiq2f85/visual/robotiq_85_base_link.dae"/>
      </geometry>
    </visual>
    <collision>
      <geometry>
        <mesh filename="./meshes/robotiq2f85/collision/robotiq_85_base_link.stl"/>
      </geometry>
    </collision>
    <inertial>
      <mass value="0.636951" />
      <origin xyz="0.0 0.0 0.0" />
      <inertia ixx = "0.000380" ixy = "0.000000" ixz = "0.000000"
          iyx = "0.000000" iyy = "0.001110" iyz = "0.000000"
          izx = "0.000000" izy = "0.000000" izz = "0.001171" />
    </inertial>
  </link>

  <joint name="robotiq_85_base_joint" type="fixed">
    <origin xyz="0 0 0.004" rpy="0 -1.57079632679 3.141592653"/>
    <parent link="robotiq_coupler"/>
    <child link="robotiq_85_base_link"/>
  </joint>

  <link name="robotiq_85_left_knuckle_link">
    <visual>
      <geometry>
        <mesh filename="./meshes/robotiq2f85/visual/robotiq_85_knuckle_link.dae"/>
      </geometry>
    </visual>
    <collision>
      <geometry>
        <mesh filename="./meshes/robotiq2f85/collision/robotiq_85_knuckle_link.stl"/>
      </geometry>
    </collision>
    <inertial>
      <mass value="0.018491" />
      <origin xyz="0.0 0.0 0.0" />
      <inertia ixx = "0.000009" ixy = "-0.000001" ixz = "0.000000"
          iyx = "-0.000001" iyy = "0.000001" iyz = "0.000000"
          izx = "0.000000" izy = "0.000000" izz = "0.000010" />
    </inertial>
  </link>

  <joint name="robotiq_85_left_knuckle_joint" type="revolute">
    <parent link="robotiq_85_base_link"/>
    <child link="robotiq_85_left_knuckle_link"/>
    <axis xyz="0 0 1"/>
    <origin rpy="3.141592653 0.0 0.0" xyz="0.05490451627 0.03060114443 0.0"/>
    <limit lower="-0.05" upper="0.80285" velocity="0.5" effort="1000"/>
    <dynamics damping="1.0" friction="1.0"/>
  </joint>

  <link name="robotiq_85_right_knuckle_link">
    <visual>
      <geometry>
        <mesh filename="./meshes/robotiq2f85/visual/robotiq_85_knuckle_link.dae"/>
      </geometry>
    </visual>
    <collision>
      <geometry>
        <mesh filename="./meshes/robotiq2f85/collision/robotiq_85_knuckle_link.stl"/>
      </geometry>
    </collision>
    <inertial>
      <mass value="0.018491" />
      <origin xyz="0.0 0.0 0.0" />
      <inertia ixx = "0.000009" ixy = "-0.000001" ixz = "0.000000"
          iyx = "-0.000001" iyy = "0.000001" iyz = "0.000000"
          izx = "0.000000" izy = "0.000000" izz = "0.000010" />
    </inertial>
  </link>

  <joint name="robotiq_85_right_knuckle_joint" type="continuous">
    <parent link="robotiq_85_base_link"/>
    <child link="robotiq_85_right_knuckle_link"/>
    <axis xyz="0 0 1"/>
    <origin rpy="0.0 0.0 0.0" xyz="0.05490451627 -0.03060114443 0.0"/>
    <limit lower="-0.05" upper="0.80285" velocity="0.5" effort="1000"/>
    <dynamics damping="1.0" friction="1.0"/>
  </joint>

  <link name="robotiq_85_left_finger_link">
    <visual>
      <geometry>
        <mesh filename="./meshes/robotiq2f85/visual/robotiq_85_finger_link.dae"/>
      </geometry>
    </visual>
    <collision>
      <geometry>
        <mesh filename="./meshes/robotiq2f85/collision/robotiq_85_finger_link.stl"/>
      </geometry>
    </collision>
    <inertial>
      <mass value="0.027309" />
      <origin xyz="0.0 0.0 0.0" />
      <inertia ixx = "0.000003" ixy = "-0.000002" ixz = "0.000000"
          iyx = "-0.000002" iyy = "0.000021" iyz = "0.000000"
          izx = "0.000000" izy = "0.000000" izz = "0.000020" />
    </inertial>
  </link>

  <joint name="robotiq_85_left_finger_joint" type="fixed">
    <parent link="robotiq_85_left_knuckle_link"/>
    <child link="robotiq_85_left_finger_link"/>
    <origin xyz="-0.00408552455 -0.03148604435 0.0" rpy="0 0 0" />
    <dynamics damping="1.0" friction="1.0"/>
  </joint>

  <link name="robotiq_85_right_finger_link">
    <visual>
      <geometry>
        <mesh filename="./meshes/robotiq2f85/visual/robotiq_85_finger_link.dae"/>
      </geometry>
    </visual>
    <collision>
      <geometry>
        <mesh filename="./meshes/robotiq2f85/collision/robotiq_85_finger_link.stl"/>
      </geometry>
    </collision>
    <inertial>
      <mass value="0.027309" />
      <origin xyz="0.0 0.0 0.0" />
      <inertia ixx = "0.000003" ixy = "-0.000002" ixz = "0.000000"
          iyx = "-0.000002" iyy = "0.000021" iyz = "0.000000"
          izx = "0.000000" izy = "0.000000" izz = "0.000020" />
    </inertial>
  </link>

  <joint name="robotiq_85_right_finger_joint" type="fixed">
    <parent link="robotiq_85_right_knuckle_link"/>
    <child link="robotiq_85_right_finger_link"/>
    <origin xyz="-0.00408552455 -0.03148604435 0.0" rpy="0 0 0" />
    <dynamics damping="1.0" friction="1.0"/>
  </joint>

  <link name="robotiq_85_left_inner_knuckle_link">
    <visual>
      <geometry>
        <mesh filename="./meshes/robotiq2f85/visual/robotiq_85_inner_knuckle_link.dae"/>
      </geometry>
    </visual>
    <collision>
      <geometry>
        <mesh filename="./meshes/robotiq2f85/collision/robotiq_85_inner_knuckle_link.stl"/>
      </geometry>
    </collision>
    <inertial>
      <mass value="0.029951" />
      <origin xyz="0.0 0.0 0.0" />
      <inertia ixx = "0.000039" ixy = "0.000000" ixz = "0.000000"
          iyx = "0.000000" iyy = "0.000005" iyz = "0.000000"
          izx = "0.000000" izy = "0.000000" izz = "0.000035" />
    </inertial>
  </link>

  <joint name="robotiq_85_left_inner_knuckle_joint" type="continuous">
    <parent link="robotiq_85_base_link"/>
    <child link="robotiq_85_left_inner_knuckle_link"/>
    <axis xyz="0 0 1"/>
    <origin xyz="0.06142 0.0127 0" rpy="${pi} 0.0 0.0" />
    <limit lower="-0.05" upper="0.80285" velocity="0.5" effort="1000"/>
    <dynamics damping="1.0" friction="1.0"/>
  </joint>

  <link name="robotiq_85_right_inner_knuckle_link">
    <visual>
      <geometry>
        <mesh filename="./meshes/robotiq2f85/visual/robotiq_85_inner_knuckle_link.dae"/>
      </geometry>
    </visual>
    <collision>
      <geometry>
        <mesh filename="./meshes/robotiq2f85/collision/robotiq_85_inner_knuckle_link.stl"/>
      </geometry>
    </collision>
    <inertial>
      <mass value="0.029951" />
      <origin xyz="0.0 0.0 0.0" />
      <inertia ixx = "0.000039" ixy = "0.000000" ixz = "0.000000"
          iyx = "0.000000" iyy = "0.000005" iyz = "0.000000"
          izx = "0.000000" izy = "0.000000" izz = "0.000035" />
    </inertial>
  </link>

  <joint name="robotiq_85_right_inner_knuckle_joint" type="continuous">
    <parent link="robotiq_85_base_link"/>
    <child link="robotiq_85_right_inner_knuckle_link"/>
    <axis xyz="0 0 1"/>
    <origin xyz="0.06142 -0.0127 0" rpy="0 0 0"/>
    <limit lower="-0.05" upper="0.80285" velocity="0.5" effort="1000"/>
    <dynamics damping="1.0" friction="1.0"/>
  </joint>

  <link name="robotiq_85_left_finger_tip_link">
    <visual>
      <geometry>
        <mesh filename="./meshes/robotiq2f85/visual/robotiq_85_finger_tip_link.dae"/>
      </geometry>
    </visual>
    <collision>
      <geometry>
        <mesh filename="./meshes/robotiq2f85/collision/robotiq_85_finger_tip_link.stl"/>
      </geometry>
    </collision>
    <inertial>
      <mass value="0.019555" />
      <origin xyz="0.0 0.0 0.0" />
      <inertia ixx = "0.000002" ixy = "0.000000" ixz = "0.000000"
          iyx = "0.000000" iyy = "0.000005" iyz = "0.000000"
          izx = "0.000000" izy = "0.000000" izz = "0.000006" />
    </inertial>
  </link> 

  <joint name="robotiq_85_left_finger_tip_joint" type="continuous">
    <parent link="robotiq_85_left_inner_knuckle_link"/>
    <child link="robotiq_85_left_finger_tip_link"/>
    <axis xyz="0 0 1"/>
    <origin xyz="0.04303959807 -0.03759940821 0.0" rpy="0.0 0.0 0.0"/>
    <limit lower="-0.80285" upper="0.05" velocity="0.5" effort="1000"/>
    <dynamics damping="1.0" friction="1.0"/>
  </joint>

  <link name="robotiq_85_right_finger_tip_link">
    <visual>
      <geometry>
        <mesh filename="./meshes/robotiq2f85/visual/robotiq_85_finger_tip_link.dae"/>
      </geometry>
    </visual>
    <collision>
      <geometry>
        <mesh filename="./meshes/robotiq2f85/collision/robotiq_85_finger_tip_link.stl"/>
      </geometry>
    </collision>
    <inertial>
      <mass value="0.019555" />
      <origin xyz="0.0 0.0 0.0" />
      <inertia ixx = "0.000002" ixy = "0.000000" ixz = "0.000000"
          iyx = "0.000000" iyy = "0.000005" iyz = "0.000000"
          izx = "0.000000" izy = "0.000000" izz = "0.000006" />
    </inertial>
  </link>

  <joint name="robotiq_85_right_finger_tip_joint" type="continuous">
    <parent link="robotiq_85_right_inner_knuckle_link"/>
    <child link="robotiq_85_right_finger_tip_link"/>
    <axis xyz="0 0 1"/>
    <origin rpy="0.0 0.0 0.0" xyz="0.04303959807 -0.03759940821  0.0"/>
    <limit lower="-0.80285" upper="0.05" velocity="0.5" effort="1000"/>
    <dynamics damping="1.0" friction="1.0"/>
  </joint>

  <link name="EE_robotiq_2f85">
    <inertial>
      <origin xyz="0 0 0" rpy="0 0 0" />
      <mass value="0.00001" />
      <inertia ixx="0.001" ixy="0.0" ixz="0.0" iyy="0.001" iyz="0.0" izz="0.001"/>
    </inertial>
    <visual>
      <geometry>
        <box size= "0.001 0.001 0.001" />
      </geometry>
    </visual>
  </link>

  <joint name="EE_robotiq_2f85_joint" type="prismatic" >
    <parent link="robotiq_85_base_link" />
    <child link="EE_robotiq_2f85" />
    <limit effort="10000" lower="0.0" upper="0.0" velocity="0.0"/>
    <axis xyz="1 0 0" />
    <origin xyz="0.128 0.0 0.0" rpy="0 0 0"/>
  </joint> -->


  <link name="world"/>
  <joint name="world_joint" type="fixed">
    <parent link="world"/>
    <child link="base_link"/>
    <origin rpy="0.0 0.0 0.0" xyz="0.0 0.0 0.0"/>
  </joint>
</robot>

